<?xml version="1.0"?>
<robot xmlns:xacro="http://ros.org/wiki/xacro" name="baxter">

  <!-- Include sensors -->
  <xacro:include filename="$(find baxter_description)/urdf/sensors/imu.urdf.xacro" />
  <xacro:include filename="$(find baxter_description)/urdf/sensors/lidar.urdf.xacro" />
  <xacro:include filename="$(find baxter_description)/urdf/sensors/camera_color.urdf.xacro" />
  <xacro:include filename="$(find baxter_description)/urdf/sensors/camera_rgbd.urdf.xacro" />

  <!-- Macro definition -->
  <xacro:macro name="baxter" params="name use_sensors:=true">

    <link name="world" />

    <!-- Pedestal -->
    <link name="base_link">
      <visual>
        <origin rpy="0 0 0" xyz="0 0 0" />
        <geometry>
          <mesh filename="package://baxter_description/meshes/base/PEDESTAL.STL" scale="1 1 1" />
        </geometry>
        <material name="darkgray">
          <color rgba=".2 .2 .2 1" />
        </material>
      </visual>
      <collision>
        <origin rpy="0 0 0" xyz="0 0 0" />
        <geometry>
          <mesh
            filename="package://baxter_description/meshes/base/pedestal_link_collision.STL"
            scale="1 1 1" />
        </geometry>
      </collision>
      <inertial>
        <origin rpy="0 0 0" xyz="0 0 0" />
        <mass value="60.86397744" />
        <inertia ixx="5.0635929" ixy="0.00103417" ixz="0.80199628" iyy="6.08689388"
          iyz="0.00105311"
          izz="4.96191932" />
      </inertial>
    </link>


    <!-- Head -->
    <link name="head">
      <visual>
        <origin rpy="0 0 0" xyz="0 0 0" />
        <geometry>
          <mesh filename="package://baxter_description/meshes/head/H0.STL" />
        </geometry>
        <material name="darkgray">
          <color rgba=".2 .2 .2 1" />
        </material>
      </visual>
      <collision>
        <origin rpy="0 0 0" xyz="0 0 0" />
        <geometry>
          <mesh filename="package://baxter_description/meshes/head/H0.STL" />
        </geometry>
      </collision>
      <inertial>
        <origin rpy="0 0 0" xyz="0 0 0" />
        <mass value="1.5" />
        <inertia ixx="0.004641" ixy="0.000159" ixz="0.000242" iyy="0.003295" iyz="-0.001324"
          izz="0.003415" />
      </inertial>
    </link>

    <link name="screen">
      <visual>
        <origin rpy="1.57079632679 0 0" xyz="0 0 0" />
        <geometry>
          <mesh filename="package://baxter_description/meshes/head/H1.STL" />
        </geometry>
        <material name="darkred">
          <color rgba=".5 .1 .1 1" />
        </material>
      </visual>
      <collision>
        <origin rpy="1.57079632679 0 0" xyz="0 0 0" />
        <geometry>
          <mesh filename="package://baxter_description/meshes/head/H1.STL" />
        </geometry>
      </collision>
      <inertial>
        <origin rpy="1.57079632679 0 0" xyz="0 0 0" />
        <mass value="1" />
        <inertia ixx="0.004006" ixy="0.000230" ixz="0.000002" iyy="0.002800" iyz="0.000029"
          izz="0.001509" />
      </inertial>
    </link>

    <link name="hat">
      <visual>
        <origin rpy="0 0 1.5708" xyz="0 0 -.08" />
        <geometry>
          <mesh filename="package://baxter_description/meshes/head/HAT.STL" scale=".01 .01 .01" />
        </geometry>
        <material name="hat">
          <color rgba=".875 .84 .757 1" />
        </material>
      </visual>
      <collision>
        <origin rpy="0 0 1.5708" xyz="0 0 -.08" />
        <geometry>
          <mesh filename="package://baxter_description/meshes/head/HAT.STL" scale=".01 .01 .01" />
        </geometry>
      </collision>
      <inertial>
        <origin rpy="0 0 1.5708" xyz="0 0 -.08" />
        <mass value=".3" />
        <inertia ixx="0.01" ixy="0.0" ixz="0.0" iyy="0.01" iyz="0.0" izz="0.01" />
      </inertial>
    </link>

    <!-- Torso -->
    <link name="torso">
      <visual>
        <origin rpy="0 0 0" xyz="0 0 0" />
        <geometry>
          <mesh filename="package://baxter_description/meshes/torso/base_link.STL" />
        </geometry>
        <material name="darkgray">
          <color rgba=".2 .2 .2 1" />
        </material>
      </visual>
      <collision>
        <origin rpy="0 0 0" xyz="0 0 0" />
        <geometry>
          <mesh filename="package://baxter_description/meshes/torso/base_link_collision.STL" />
        </geometry>
      </collision>
      <inertial>
        <mass value="35.336455" />
        <inertia ixx="1.849155" ixy="-0.000354" ixz="-0.154188" iyy="1.662671"
          iyz="0.003292"
          izz="0.802239" />
      </inertial>
    </link>


    <!-- ====== LEFT ARM LINKS ====== -->

    <!-- Left upper shoulder -->
    <link name="left_upper_shoulder">
      <visual>
        <origin rpy="0 0 1.5708" xyz="0 0 0" />
        <geometry>
          <mesh filename="package://baxter_description/meshes/upper_shoulder/S0.STL" />
        </geometry>
        <material name="darkgray">
          <color rgba=".2 .2 .2 1" />
        </material>
      </visual>
      <collision>
        <origin rpy="0 0 1.5708" xyz="0 0 0" />
        <geometry>
          <!--cylinder
          length="0.2722" radius="0.06" /-->
          <mesh filename="package://baxter_description/meshes/upper_shoulder/S0.STL" />
        </geometry>
      </collision>
      <inertial>
        <origin rpy="0 0 0" xyz="0.01783 0.00086 0.19127" />
        <mass value="5.70044" />
        <inertia ixx="0.04709102262" ixy="0.00012787556" ixz="0.00614870039"
          iyy="0.03766976455"
          iyz="0.00078086899" izz="0.03595988478" />
      </inertial>
    </link>

    <!-- Left lower shoulder -->
    <link name="left_lower_shoulder">
      <visual>
        <origin rpy="1.5708 0 1.5708" xyz="0 0 0" />
        <geometry>
          <mesh filename="package://baxter_description/meshes/lower_shoulder/S1.STL" />
        </geometry>
        <material name="darkred">
          <color rgba=".5 .1 .1 1" />
        </material>
      </visual>
      <collision>
        <origin rpy="1.5708 0 1.5708" xyz="0 0 0" />
        <geometry>
          <!--cylinder
          length="0.12" radius="0.06" /-->
          <mesh filename="package://baxter_description/meshes/lower_shoulder/S1.STL" />
        </geometry>
      </collision>
      <inertial>
        <origin rpy="1.5708 0 1.5708" xyz="0 0 0" />
        <mass value="3.22698" />
        <inertia ixx="0.01175209419" ixy="-0.00030096398" ixz="0.00207675762"
          iyy="0.0278859752"
          iyz="-0.00018821993" izz="0.02078749298" />
      </inertial>
    </link>

    <!-- Left upper elbow -->
    <link name="left_upper_elbow">
      <visual>
        <origin rpy="1.5708 1.5708 3.1416" xyz="0 0 0" />
        <geometry>
          <mesh filename="package://baxter_description/meshes/upper_elbow/E0.STL" />
        </geometry>
        <material name="darkred">
          <color rgba=".5 .1 .1 1" />
        </material>
      </visual>
      <collision>
        <origin rpy="1.5708 1.5708 3.1416" xyz="0 0 0" />
        <geometry>
          <!--cylinder
          length="0.107" radius="0.06" /-->
          <mesh filename="package://baxter_description/meshes/upper_elbow/E0.STL" />
        </geometry>
      </collision>
      <inertial>
        <origin rpy="1.5708 1.5708 3.1416" xyz="0 0 0" />
        <mass value="4.31272" />
        <inertia ixx="0.02661733557" ixy="0.00029270634" ixz="0.00392189887"
          iyy="0.02844355207"
          iyz="0.0010838933" izz="0.01248008322" />
      </inertial>
    </link>

    <!-- Left lower elbow -->
    <link name="left_lower_elbow">
      <visual>
        <origin rpy="-1.5708 1.5708 1.5708" xyz="0 0 0" />
        <geometry>
          <mesh filename="package://baxter_description/meshes/lower_elbow/E1.STL" />
        </geometry>
        <material name="darkred">
          <color rgba=".5 .1 .1 1" />
        </material>
      </visual>
      <collision>
        <origin rpy="-1.5708 1.5708 1.5708" xyz="0 0 0" />
        <geometry>
          <!--cylinder
          length="0.10" radius="0.06" /-->
          <mesh filename="package://baxter_description/meshes/lower_elbow/E1.STL" />
        </geometry>
      </collision>
      <inertial>
        <origin rpy="-1.5708 1.5708 1.5708" xyz="0 0 0" />
        <mass value="2.07206" />
        <inertia ixx="0.00711582686" ixy="0.00036036173" ixz="0.0007459496"
          iyy="0.01318227876"
          iyz="-0.00019663418" izz="0.00926852064" />
      </inertial>
    </link>

    <!-- Left upper forearm -->
    <link name="left_upper_forearm">
      <visual>
        <origin rpy="3.1416 0 -1.5708" xyz="0 0 0" />
        <geometry>
          <mesh filename="package://baxter_description/meshes/upper_forearm/W0.STL" />
        </geometry>
        <material name="darkred">
          <color rgba=".5 .1 .1 1" />
        </material>
      </visual>
      <collision>
        <origin rpy="3.1416 0 -1.5708" xyz="0 0 0" />
        <geometry>
          <!--cylinder
          length="0.088" radius="0.06" /-->
          <mesh filename="package://baxter_description/meshes/upper_forearm/W0.STL" />
        </geometry>
      </collision>
      <inertial>
        <origin rpy="3.1416 0 -1.5708" xyz="0 0 0" />
        <mass value="2.24665" />
        <inertia ixx="0.01667742825" ixy="0.00018403705" ixz="0.00018657629"
          iyy="0.01675457264"
          iyz="-0.00064732352" izz="0.0037463115" />
      </inertial>
    </link>

    <!-- Left lower forearm -->
    <link name="left_lower_forearm">
      <visual>
        <origin rpy="0 1.5708 0" xyz="0 0 0" />
        <geometry>
          <mesh filename="package://baxter_description/meshes/lower_forearm/W1.STL" />
        </geometry>
        <material name="darkgray">
          <color rgba=".2 .2 .2 1" />
        </material>
      </visual>
      <collision>
        <origin rpy="0 1.5708 0" xyz="0 0 0" />
        <geometry>
          <!--cylinder
          length="0.10" radius="0.06" /-->
          <mesh filename="package://baxter_description/meshes/lower_forearm/W1.STL" />
        </geometry>
      </collision>
      <inertial>
        <origin rpy="0 1.5708 0" xyz="0 0 0" />
        <mass value="1.60979" />
        <inertia ixx="0.00387607152" ixy="-0.00044384784" ixz="-0.00021115038"
          iyy="0.00700537914"
          iyz="0.00015348067" izz="0.0055275524" />
      </inertial>
    </link>

    <!-- Left wrist -->
    <link name="left_wrist">
      <visual>
        <origin rpy="0 3.1416 -1.5708" xyz="0 0 0" />
        <geometry>
          <mesh filename="package://baxter_description/meshes/wrist/W2.STL" />
        </geometry>
        <material name="darkred">
          <color rgba=".5 .1 .1 1" />
        </material>
      </visual>
      <collision>
        <origin rpy="0 3.1416 -1.5708" xyz="0 0 0" />
        <geometry>
          <!--cylinder
          length="0.165" radius="0.06" /-->
          <mesh filename="package://baxter_description/meshes/wrist/W2.STL" />
        </geometry>
      </collision>
      <inertial>
        <origin rpy="0 3.1416 -1.5708" xyz="0 0 0" />
        <mass value="0.35093" />
        <inertia ixx="0.00025289155" ixy="0.00000575311" ixz="-0.00000159345"
          iyy="0.0002688601"
          iyz="-0.00000519818" izz="0.0003074118" />
      </inertial>
    </link>

    <!-- Left grippers -->
    <link name="left_grippers">
      <visual>
        <origin rpy="0 3.1416 0" xyz="0 0 0" />
        <geometry>
          <mesh filename="package://baxter_description/meshes/grippers/GRIPPER.STL" />
        </geometry>
        <material name="darkred">
          <color rgba=".5 .1 .1 1" />
        </material>
      </visual>
      <collision>
        <origin rpy="0 3.1416 0" xyz="0 0 0" />
        <geometry>
          <mesh filename="package://baxter_description/meshes/grippers/GRIPPER.STL" />
        </geometry>
      </collision>
      <inertial>
        <origin rpy="0 3.1416 0" xyz="0 0 0" />
        <mass value=".5" />
        <inertia ixx="0.01" ixy="0.0" ixz="0.0" iyy="0.01" iyz="0.0" izz="0.01" />
      </inertial>
    </link>


    <!-- ====== RIGHT ARM LINKS ====== -->

    <!-- Right upper shoulder -->
    <link name="right_upper_shoulder">
      <visual>
        <origin rpy="0 0 -1.5708" xyz="0 0 0" />
        <geometry>
          <mesh filename="package://baxter_description/meshes/upper_shoulder/S0.STL" />
        </geometry>
        <material name="darkgray">
          <color rgba=".2 .2 .2 1" />
        </material>
      </visual>
      <collision>
        <origin rpy="0 0 -1.5708" xyz="0 0 0" />
        <geometry>
          <!--cylinder
          length="0.2722" radius="0.06" /-->
          <mesh filename="package://baxter_description/meshes/upper_shoulder/S0.STL" />
        </geometry>
      </collision>
      <inertial>
        <origin rpy="0 0 -1.5708" xyz="0 0 0" />
        <mass value="5.70044" />
        <inertia ixx="0.04709102262" ixy="0.00012787556" ixz="0.00614870039"
          iyy="0.03766976455"
          iyz="0.00078086899" izz="0.03595988478" />
      </inertial>
    </link>

    <!-- Right lower shoulder -->
    <link name="right_lower_shoulder">
      <visual>
        <origin rpy="1.5708 0 -1.5708" xyz="0 0 0" />
        <geometry>
          <mesh filename="package://baxter_description/meshes/lower_shoulder/S1.STL" />
        </geometry>
        <material name="darkred">
          <color rgba=".5 .1 .1 1" />
        </material>
      </visual>
      <collision>
        <origin rpy="1.5708 0 -1.5708" xyz="0 0 0" />
        <geometry>
          <!--cylinder
          length="0.12" radius="0.06" /-->
          <mesh filename="package://baxter_description/meshes/lower_shoulder/S1.STL" />
        </geometry>
      </collision>
      <inertial>
        <origin rpy="1.5708 0 -1.5708" xyz="0 0 0" />
        <mass value="3.22698" />
        <inertia ixx="0.01175209419" ixy="-0.00030096398" ixz="0.00207675762"
          iyy="0.0278859752"
          iyz="-0.00018821993" izz="0.02078749298" />
      </inertial>
    </link>

    <!-- Right upper elbow -->
    <link name="right_upper_elbow">
      <visual>
        <origin rpy="0 1.5708 -1.5708" xyz="0 0 0" />
        <geometry>
          <mesh filename="package://baxter_description/meshes/upper_elbow/E0.STL" />
        </geometry>
        <material name="darkred">
          <color rgba=".5 .1 .1 1" />
        </material>
      </visual>
      <collision>
        <origin rpy="0 1.5708 -1.5708" xyz="0 0 0" />
        <geometry>
          <!--cylinder
          length="0.107" radius="0.06" /-->
          <mesh filename="package://baxter_description/meshes/upper_elbow/E0.STL" />
        </geometry>
      </collision>
      <inertial>
        <origin rpy="0 1.5708 -1.5708" xyz="0 0 0" />
        <mass value="4.31272" />
        <inertia ixx="0.02661733557" ixy="0.00029270634" ixz="0.00392189887"
          iyy="0.02844355207"
          iyz="0.0010838933" izz="0.01248008322" />
      </inertial>
    </link>

    <!-- Right lower elbow -->
    <link name="right_lower_elbow">
      <visual>
        <origin rpy="-1.5708 1.5708 1.5708" xyz="0 0 0" />
        <geometry>
          <mesh filename="package://baxter_description/meshes/lower_elbow/E1.STL" />
        </geometry>
        <material name="darkred">
          <color rgba=".5 .1 .1 1" />
        </material>
      </visual>
      <collision>
        <origin rpy="-1.5708 1.5708 1.5708" xyz="0 0 0" />
        <geometry>
          <!--cylinder
          length="0.10" radius="0.06" /-->
          <mesh filename="package://baxter_description/meshes/lower_elbow/E1.STL" />
        </geometry>
      </collision>
      <inertial>
        <origin rpy="-1.5708 1.5708 1.5708" xyz="0 0 0" />
        <mass value="2.07206" />
        <inertia ixx="0.00711582686" ixy="0.00036036173" ixz="0.0007459496"
          iyy="0.01318227876"
          iyz="-0.00019663418" izz="0.00926852064" />
      </inertial>
    </link>

    <!-- Right upper forearm -->
    <link name="right_upper_forearm">
      <visual>
        <origin rpy="3.1416 0 1.5708" xyz="0 0 0" />
        <geometry>
          <mesh filename="package://baxter_description/meshes/upper_forearm/W0.STL" />
        </geometry>
        <material name="darkred">
          <color rgba=".5 .1 .1 1" />
        </material>
      </visual>
      <collision>
        <origin rpy="3.1416 0 1.5708" xyz="0 0 0" />
        <geometry>
          <!--cylinder
          length="0.088" radius="0.06" /-->
          <mesh filename="package://baxter_description/meshes/upper_forearm/W0.STL" />
        </geometry>
      </collision>
      <inertial>
        <origin rpy="3.1416 0 1.5708" xyz="0 0 0" />
        <mass value="2.24665" />
        <inertia ixx="0.01667742825" ixy="0.00018403705" ixz="0.00018657629"
          iyy="0.01675457264"
          iyz="-0.00064732352" izz="0.0037463115" />
      </inertial>
    </link>

    <!-- Right_lower forearm -->
    <link name="right_lower_forearm">
      <visual>
        <origin rpy="0 1.5708 -3.1416" xyz="0 0 0" />
        <geometry>
          <mesh filename="package://baxter_description/meshes/lower_forearm/W1.STL" />
        </geometry>
        <material name="darkgray">
          <color rgba=".2 .2 .2 1" />
        </material>
      </visual>
      <collision>
        <origin rpy="0 1.5708 -3.1416" xyz="0 0 0" />
        <geometry>
          <!--cylinder
          length="0.10" radius="0.06" /-->
          <mesh filename="package://baxter_description/meshes/lower_forearm/W1.STL" />
        </geometry>
      </collision>
      <inertial>
        <origin rpy="0 1.5708 -3.1416" xyz="0 0 0" />
        <mass value="1.60979" />
        <inertia ixx="0.00387607152" ixy="-0.00044384784" ixz="-0.00021115038"
          iyy="0.00700537914"
          iyz="0.00015348067" izz="0.0055275524" />
      </inertial>
    </link>

    <!-- Right wrist -->
    <link name="right_wrist">
      <visual>
        <origin rpy="0 3.1416 1.5708" xyz="0 0 0" />
        <geometry>
          <mesh filename="package://baxter_description/meshes/wrist/W2.STL" />
        </geometry>
        <material name="darkred">
          <color rgba=".5 .1 .1 1" />
        </material>
      </visual>
      <collision>
        <origin rpy="0 3.1416 1.5708" xyz="0 0 0" />
        <geometry>
          <!--cylinder
          length="0.165" radius="0.06" /-->
          <mesh filename="package://baxter_description/meshes/wrist/W2.STL" />
        </geometry>
      </collision>
      <inertial>
        <origin rpy="0 3.1416 1.5708" xyz="0 0 0" />
        <mass value="0.35093" />
        <inertia ixx="0.00025289155" ixy="0.00000575311" ixz="-0.00000159345"
          iyy="0.0002688601"
          iyz="-0.00000519818" izz="0.0003074118" />
      </inertial>
    </link>

    <!-- Right grippers -->
    <link name="right_grippers">
      <visual>
        <origin rpy="0 -3.1416 0" xyz="0 0 0" />
        <geometry>
          <mesh filename="package://baxter_description/meshes/grippers/GRIPPER.STL" />
        </geometry>
        <material name="darkred">
          <color rgba=".5 .1 .1 1" />
        </material>
      </visual>
      <collision>
        <origin rpy="0 -3.1416 0" xyz="0 0 0" />
        <geometry>
          <mesh filename="package://baxter_description/meshes/grippers/GRIPPER.STL" />
        </geometry>
      </collision>
      <inertial>
        <origin rpy="0 -3.1416 0" xyz="0 0 0" />
        <mass value=".5" />
        <inertia ixx="0.01" ixy="0.0" ixz="0.0" iyy="0.01" iyz="0.0" izz="0.01" />
      </inertial>
    </link>


    <!-- TODO: Add joints/links for baxter (arms, wheels, etc.) -->
    <!-- ====== JOINTS ====== -->
    <joint name="world_to_base" type="fixed">
      <parent link="world" />
      <child link="base_link" />
      <origin xyz="0 0 .924" rpy="0 0 0" />
    </joint>

    <!-- head - screen -->
    <joint name="head_screen" type="fixed">
      <origin rpy="0 0 0" xyz=".07 0 0" />
      <parent link="head" />
      <child link="screen" />
    </joint>

    <!-- pedestal - torso -->
    <joint name="pedestal_torso" type="fixed">
      <parent link="base_link" />
      <child link="torso" />
      <origin xyz="0 0 0" rpy="0 0 0" />
    </joint>

    <!-- torso - head -->
    <joint name="torso_head" type="revolute">
      <parent link="torso" />
      <child link="head" />
      <origin xyz=".062 0 .6875" rpy="0 0 0" />
      <axis xyz="0 0 1" />
      <limit lower="-0.7854" upper="0.7854" effort="50" velocity="1.5" />
    </joint>

    <!-- head - hat-->
    <joint name="head_hat" type="fixed">
      <parent link="head" />
      <child link="hat" />
      <!-- <origin rpy="0 0 0" xyz=".063 0 .39" /> -->
      <origin rpy="0 0 0" xyz="0 0 .18" />
    </joint>


    <!-- ========== LEFT ARM ========== -->

    <!-- torso - left upper shoulder -->
    <joint name="torso_left_upper_shoulder" type="revolute">
      <parent link="torso" />
      <child link="left_upper_shoulder" />
      <origin rpy="0 0 0" xyz=".063 .255 .025" />
      <axis xyz="0 0 1" />
      <limit lower="-1.5708" upper="0.89" effort="50" velocity="1.5" />
    </joint>

    <!-- left upper shoulder - left lower shoulder -->
    <joint name="left_upper_shoulder_lower_shoulder" type="revolute">
      <parent link="left_upper_shoulder" />
      <child link="left_lower_shoulder" />
      <origin rpy="0 0 0" xyz="0 .075 .275" />
      <axis xyz="1 0 0" />
      <limit lower="-0.5236" upper="1.0472" effort="50" velocity="1.5" />
    </joint>

    <!-- left lower shoulder - left upper elbow -->
    <joint name="left_lower_shoulder_upper_elbow" type="revolute">
      <parent link="left_lower_shoulder" />
      <child link="left_upper_elbow" />
      <origin rpy="0 0 0" xyz="0 .1 0" />
      <axis xyz="0 1 0" />
      <limit lower="-1.5708" upper="1.5708" effort="50" velocity="1.5" />
    </joint>

    <!-- left upper elbow - left lower elbow -->
    <joint name="left_upper_elbow_lower_elbow" type="revolute">
      <parent link="left_upper_elbow" />
      <child link="left_lower_elbow" />
      <origin rpy="0 0 0" xyz="0 .262 -.069" />
      <axis xyz="1 0 0" />
      <limit lower="-0.0524" upper="1.5708" effort="50" velocity="1.5" />
    </joint>

    <!-- left lower elbow - left upper forearm -->
    <joint name="left_lower_elbow_upper_forearm" type="revolute">
      <parent link="left_lower_elbow" />
      <child link="left_upper_forearm" />
      <origin rpy="0 0 0" xyz="0 0 -.1" />
      <axis xyz="0 0 1" />
      <limit lower="-3.0543" upper="3.0543" effort="50" velocity="1.5" />
    </joint>

    <!-- left upper forearm - left lower forearm -->
    <joint name="left_upper_forearm_lower_forearm" type="revolute">
      <parent link="left_upper_forearm" />
      <child link="left_lower_forearm" />
      <origin rpy="0 0 0" xyz="0 -.012 -.27" />
      <axis xyz="1 0 0" />
      <limit lower="-1.5708" upper="1.5708" effort="50" velocity="1.5" />
    </joint>

    <!-- left lower forearm - left wrist -->
    <joint name="left_lower_forearm_wrist" type="revolute">
      <parent link="left_lower_forearm" />
      <child link="left_wrist" />
      <origin rpy="0 0 0" xyz="0 0 -.112" />
      <axis xyz="0 0 1" />
      <limit lower="-3.0543" upper="3.0543" effort="50" velocity="1.5" />
    </joint>

    <!-- left wrist - left gripper -->
    <joint name="left_wrist_gripper" type="revolute">
      <parent link="left_wrist" />
      <child link="left_grippers" />
      <origin rpy="0 0 0" xyz="0 0 -.143" />
      <axis xyz="0 0 1" />
      <limit lower="-1.5708" upper="1.5708" effort="50" velocity="1.5" />
    </joint>


    <!-- ====== RIGHT ARM ====== -->
    <!-- torso - right upper shoulder -->
    <joint name="torso_right_upper_shoulder" type="revolute">
      <parent link="torso" />
      <child link="right_upper_shoulder" />
      <origin rpy="0 0 0" xyz=".063 -.255 .025" />
      <axis xyz="0 0 1" />
      <!-- <limit lower="-2.46" upper="0.89" effort="50" velocity="1.5" /> -->
      <limit lower="-0.89" upper="1.5708" effort="50" velocity="1.5" />
    </joint>

    <!-- right upper shoulder - right lower shoulder -->
    <joint name="right_upper_shoulder_lower_shoulder" type="revolute">
      <parent link="right_upper_shoulder" />
      <child link="right_lower_shoulder" />
      <origin rpy="0 0 0" xyz="0 -.075 .275" />
      <axis xyz="1 0 0" />
      <limit lower="-1.0472" upper="0.5236" effort="50" velocity="1.5" />
    </joint>

    <!-- right lower shoulder - right upper elbow -->
    <joint name="right_lower_shoulder_upper_elbow" type="revolute">
      <parent link="right_lower_shoulder" />
      <child link="right_upper_elbow" />
      <origin rpy="0 0 0" xyz="0 -.1 0" />
      <axis xyz="0 1 0" />
      <limit lower="-1.5708" upper="1.5708" effort="50" velocity="1.5" />
    </joint>

    <!-- right upper elbow - right lower elbow -->
    <joint name="right_upper_elbow_lower_elbow" type="revolute">
      <parent link="right_upper_elbow" />
      <child link="right_lower_elbow" />
      <origin rpy="0 0 0" xyz="0 -.262 -.069" />
      <axis xyz="1 0 0" />
      <limit lower="-1.5708" upper="0.0524" effort="50" velocity="1.5" />
    </joint>

    <!-- right lower elbow - right upper forearm -->
    <joint name="right_lower_elbow_upper_forearm" type="revolute">
      <parent link="right_lower_elbow" />
      <child link="right_upper_forearm" />
      <origin rpy="0 0 0" xyz="0 0 -0.1" />
      <axis xyz="0 0 1" />
      <limit lower="-3.0543" upper="3.0543" effort="50" velocity="1.5" />
    </joint>

    <!-- right upper forearm - right lower forearm -->
    <joint name="right_upper_forearm_lower_forearm" type="revolute">
      <parent link="right_upper_forearm" />
      <child link="right_lower_forearm" />
      <origin rpy="0 0 0" xyz="0 .012 -.27" />
      <axis xyz="1 0 0" />
      <limit lower="-1.5708" upper="1.5708" effort="50" velocity="1.5" />
    </joint>

    <!-- right lower forearm - right wrist -->
    <joint name="right_lower_forearm_wrist" type="revolute">
      <parent link="right_lower_forearm" />
      <child link="right_wrist" />
      <origin rpy="0 0 0" xyz="0 0 -.112" />
      <axis xyz="0 0 1" />
      <limit lower="-3.0543" upper="3.0543" effort="50" velocity="1.5" />
    </joint>

    <!-- right wrist - right gripper -->
    <joint name="right_wrist_gripper" type="revolute">
      <parent link="right_wrist" />
      <child link="right_grippers" />
      <origin rpy="0 0 0" xyz="0 0 -.143" />
      <axis xyz="0 0 1" />
      <limit lower="-1.5708" upper="1.5708" effort="50" velocity="1.5" />
    </joint>


    <xacro:if value="${use_sensors}">
      <xacro:imu parent="base_link" frame="imu_link" />
      <xacro:lidar parent="hat" frame="lidar_link" />
      <xacro:camera_color parent="screen" frame="camera_link" />
    </xacro:if>
  </xacro:macro>


  <!--xacro:baxter
  name="baxter" /-->
</robot>